import React from 'react';
import { render, screen } from '@testing-library/react';
import { ErrorBoundary } from '../error-boundary';

// Component that throws an error
const ThrowError = ({ shouldThrow }: { shouldThrow: boolean }) => {
  if (shouldThrow) {
    throw new Error('Test error');
  }
  return <div>No error</div>;
};

describe('ErrorBoundary', () => {
  // Suppress console.error for these tests
  const originalError = console.error;
  beforeAll(() => {
    console.error = jest.fn();
  });
  afterAll(() => {
    console.error = originalError;
  });

  it('renders children when there is no error', () => {
    render(
      <ErrorBoundary>
        <ThrowError shouldThrow={false} />
      </ErrorBoundary>
    );
    
    expect(screen.getByText('No error')).toBeInTheDocument();
  });

  it('renders error fallback when there is an error', () => {
    render(
      <ErrorBoundary>
        <ThrowError shouldThrow={true} />
      </ErrorBoundary>
    );
    
    expect(screen.getByText(/something went wrong/i)).toBeInTheDocument();
  });

  it('renders custom fallback component', () => {
    const CustomFallback = () => <div>Custom error message</div>;
    
    render(
      <ErrorBoundary fallback={CustomFallback}>
        <ThrowError shouldThrow={true} />
      </ErrorBoundary>
    );
    
    expect(screen.getByText('Custom error message')).toBeInTheDocument();
  });

  it('calls onError callback when error occurs', () => {
    const onError = jest.fn();
    
    render(
      <ErrorBoundary onError={onError}>
        <ThrowError shouldThrow={true} />
      </ErrorBoundary>
    );
    
    expect(onError).toHaveBeenCalledWith(
      expect.any(Error),
      expect.any(Object)
    );
  });
});